Workbook

Sheet 2021
A1: TABELA DE PREÇO
A2: CLIENTES | B2: PELETIZAR | C2: FLANELAR | D2: CALANDRAR | E2: MALHA P/ FARDO
A3: AIR SLAID | E3: 10,50 O KILO
A4: AMBERT TEXTIL | C4: ord 12221,12170 2xR$0,35 p/mts
A5: BERGON COMERCIO | C5: demais ordens R$0,37 p/mts 16/03
A6: BERGON COMERCIO | C6: 2x 0,40 p/mts
A7: CHUMBRECAS/MX72 | C7: 2x 0,60 p/mts
A8: COLEÇÃO TEXTIL | B8: 1x 0,30 p/mts
A9: COMPOMAX | C9: 0,27 P/mts
A10: COVOLAN BENEFIC. | B10: 1x 0,30 p/mts | E10: 10,50 O KILO
A11: CIPATEX | C11: DUBLAR C/ SPUNLACE 1,20
A12: ECOSIMPLE IND. | B12: 1,8 P/mts | C12: DUBLAGEM TUPY 4,10 / TERMOFIXAR 1,20
A13: IBIRAPUERA TEXTIL | B13: 0,95p/mts
A14: IRMAOS JURGENSEN | B14: 1x 0,30 p/mts
A15: INNOVATIV IND. | B15: 1x 0,45 p/mts | C15: 2x -0,65 p/mts / Lona 0,75 p/mts / TELA DUBLARE 1X = 0,50 p/mts / Felpar 0,75 | E15: 10,50 O KILO
A16: IRINEU MENEGHEL | C16: 1X 0,40 p/mts
A17: ITALYTEX TEXTIL | D17: 1x 0,30 p/mts
A18: MAC ROSE | C18: 3x 0,75 p/mts
A19: J.BESAN COMERCIAL | C19: 1X 0,30 p/mts 2x 0,50 p/mts
A20: NOSSA SRA DO BELEM | B20: 1x 0,30 p/mts
A21: SELENE IND. | B21: 1x 0,28 p/mts | C21: 1X 0,30 p/mts 2x 0,50 p/mts | D21: 0,77 p/mts
A22: TEXION TEXTIL | B22: 1x 0,30 p/mts | C22: Calandrar e Felpar 0,80 p/ mts /Calandrar e Felpar Million 1,10 p/mts | D22: 0,50 p/mts
A23: TEXION TEXTIL | C23: DUBLAR C/ CRETONE 0,70 DUBLAR C/ SPUNLACE 0,70 | D23: LONA CUSTOM 0,80
A24: TEXPOY TEXTIL | C24: 2x 0,50 p/mts 3x 0,70 p/mts
A25: MX72 | C25: 2x 0,65 p/mts
A26: TEXTIL FAVERO | B26: 1x 0,30 p/mts | C26: 3x 0,75 p/mts
A27: TRAMAS DO BRASIL | E27: 10,50 O KILO
A28: TEC. PANAMERICANA | B28: 0,45 p/mts
A29: ZAVATEX | D29: 0,50 P/MTS

Sheet 2022-2023
B2: Cliente | C2: Processo | D2: Artigo | E2: Passagem | F2: Valor | G2: Coluna1 | H2: Obsevação
B3: Wameltex (Eliseu/Grilo) | C3: Dublagem/Espelhamento | E3: 1 | F3: 1.05 | G3: p/m | H3: 1.15
B4: Air Slaid | C4: Malha | F4: 15.6 | G4: p/ kg
B5: Ambert Textil | C5: Flanelar | D5: Ordem 12221,12170 | E5: 2 | F5: 0.55 | G5: p/ m | H5: 0.63
B6: Aparatos | G6: 5.12 | H6: 10.7
B7: Aparatos | D7: C/NOSSO FORRO | H7: 6.9
B8: Aparatos | D8: ESPELHAMENTO | H8: 6.7
B9: Aparatos | D9: C/TNT | H9: 6.1
B10: Bergon Comércio | C10: Flanelar | D10: 0,50 E LEVA E RETIRA | E10: 2 | F10: 0.55 | G10: p/ m | H10: 0.6
B11: Bergon Comércio | C11: Flanelar | D11: Demais ordens | F11: 0.37 | G11: p/ m
B12: Calmart | C12: Lixar | E12: 1 | G12: p/m | H12: 0.6
B13: Calmart | C13: Dublagem | E13: 1 | G13: p/m | H13: 2.14
B14: Chumbrecas/MX72 | C14: Flanelar | E14: 2 | F14: 0.6 | G14: p/ m | H14: 1
B15: Cipatex | C15: Flanelar | D15: Dublar com Spunlace | F15: 1.4 | G15: p/ m | H15: 1.61
B16: Coleção Textil | C16: Peletizar | E16: 1 | F16: 0.3 | G16: p/ m | H16: 0.34
B17: Compomax | C17: Flanelar | F17: 0.27 | G17: p/ m | H17: 0.3
B18: Covolan Benefic. | C18: Peletizar | E18: 1 | F18: 0.3 | G18: p/ m | H18: 0.34
B19: Covolan Benefic. | C19: Malha | F19: 15.6 | G19: p/ kg
B20: DB RAINBOW | C20: Dublagem | E20: 1 | F20: 2.2 | G20: p/m | H20: 2.55
B21: Ecosimple Ind. | C21: Flanelar/Peletizar | D21: LISO/LISTRA | F21: 1.8 | G21: p/ m | H21: 2.57
B22: Ecosimple Ind. | C22: Dublagem/Cretone | D22: Dublagem Tupy/New Tweed | F22: 5.63 | G22: p/ m | H22: 6.19
B23: Ecosimple Ind. | C23: Calandrar/Termofixar | E23: 1 | F23: 1.4 | G23: p/m | H23: 1.61
B24: Ecosimple Ind. | C24: Dublagem TNT | D24: TNT= R$ 1,42 | G24: p/m | H24: 4.63
B25: Ecosimple Ind. | C25: Calandrar | G25: p/m
B26: Ecosimple Ind. | C26: Flanelar | D26: Rubus flanelado/Vision/lana Color | E26: 4 | F26: 4.2 | G26: p/m | H26: 4.83
B27: Ecosimple Ind. | C27: Peletizar | D27: Lona Duty Stone/Lona Cargo | E27: 1 | F27: 2.8 | G27: p/m | H27: 3.22
B28: Ecosimple Ind. | C28: Felpar/Flanelar | D28: Lana Vert/Grain/Max/Milao/Alana /alba | E28: 1 | F28: 2.3 | G28: p/m | H28: 2.64
B29: Ecosimple Ind. | C29: Espelhamento | D29: C/ Filme Single | E29: 1 | F29: 2.4 | G29: p/m | H29: 2.76
B30: Ecosimple Ind. | C30: Dublag. Cretone lote de tecido comprado | G30: p/m | H30: 2.4
B31: Ecosimple Ind. | C31: Calandrar/Felpar | G31: p/m | H31: 4.25
B32: Ecosimple Ind. | C32: Flanelar | G32: p/ m | H32: 1.61
B33: Ecosimple Ind. | C33: Flanelar | D33: Casaco /1002-1916090170 | G33: p/m | H33: 4.83
B34: Ecosimple Ind. | C34: Flanelar | D34: Tela | E34: 2 | G34: p/m | H34: 2.64
B35: Ecosimple Ind. | C35: Termofixar | D35: Sami/Maquinetado/Sublime | G35: p/m | H35: 3.65
B36: Ecosimple Ind. | C36: Espelhamento / At 150 ou 100 | D36: Filme + Mão de obra | G36: p/m | H36: 4.6
B37: Ecosimple Ind. | C37: Termofixar + flanelar | D37: 1002090010-0000 | E37: 2 | G37: p/m | H37: 3.65
B38: DB RAINBOW | C38: Flanelar/Peletizado | E38: 1 | F38: 0.3 | G38: p/m | H38: 0.55
B39: Engebank | C39: Dublagem | E39: 1 | G39: p/m | H39: 8.6
B40: Estopas Americana | C40: Dublagem | E40: 1 | F40: 5.2 | G40: p/m | H40: 5.98
B41: Estopas Americana | C41: Flanela | E41: 1 | F41: 0.85 | G41: p/m | H41: 0.98
...

Sheet 2024
B1: Cliente | C1: Processo | D1: Artigo | E1: Passadas | F1: Valor anterior | G1: Valor atual | H1: Unid | I1: Preço/metro | J1: Data de atualização | K1: Obs | L1: MO | M1: Colas | N1: Forro
B2: Ademir Maceti | C2: Calandra | G2: 0.65 | H2: metro linear
B3: Ademir Maceti | C3: Emborrachamento | G3: =4.1+1.5 -> 5.6 | H3: metro linear
B4: AG Textil Eireli | C4: Peletização | E4: 1 | G4: 0.65 | H4: metro linear | I4: =G4/E4 -> 0.65 | L4: =G4-M4-N4 -> 0.65 | M4: =IF(B4="Texion Textil",0,IF(C4="Malha",'Custos insumos'!$B$24,IF(C4="Dublagem Cretone",'Custos insumos'!$D$7,IF(C4="Dublagem Spun",'Custos insumos'!$D$4,IF(C4="Espelhamento",'Custos insumos'!$B$11,IF(C4="Espelhamento 2x",2*'Custos insumos'!$B$11,IF(C4="Esp. + Pel.",'Custos insumos'!$B$11,IF(C4="Pel. + Spun",'Custos insumos'!$D$4,IF(C4="Dublagem Cretone PES",'Custos insumos'!$D$7,IF(C4="Dublagem Barreira",'Custos insumos'!$D$11,IF(C4="Dublagem - MO + Filme",'Custos insumos'!$D$4,))))))))))) -> 0 | N4: =IF(B4="Texion Textil",0,IF(B4="Três Elos",0,IF(C4="Malha",0,IF(C4="Dublagem Cretone",'Custos insumos'!$D$23,IF(C4="Dublagem Spun",'Custos insumos'!$D$19,IF(C4="Espelhamento",0,IF(C4="Espelhamento 2x",0,IF(C4="Esp. + Pel.",0,IF(C4="Pel. + Spun",'Custos insumos'!$D$19,IF(C4="Dublagem Cretone PES",'Custos insumos'!$F$25,IF(C4="Dublagem Barreira",'Custos insumos'!$D$22,))))))))))) -> 0
B5: Air Slaid | C5: Malha | E5: 1 | F5: 18.9 | G5: 20.9 | H5: kg | I5: =G5/E5 -> 20.9 | J5: 45301 | L5: =G5-M5-N5 -> 8.4 | M5: =IF(B5="Texion Textil",0,IF(C5="Malha",'Custos insumos'!$B$24,IF(C5="Dublagem Cretone",'Custos insumos'!$D$7,IF(C5="Dublagem Spun",'Custos insumos'!$D$4,IF(C5="Espelhamento",'Custos insumos'!$B$11,IF(C5="Espelhamento 2x",2*'Custos insumos'!$B$11,IF(C5="Esp. + Pel.",'Custos insumos'!$B$11,IF(C5="Pel. + Spun",'Custos insumos'!$D$4,IF(C5="Dublagem Cretone PES",'Custos insumos'!$D$7,IF(C5="Dublagem Barreira",'Custos insumos'!$D$11,IF(C5="Dublagem - MO + Filme",'Custos insumos'!$D$4,))))))))))) -> 12.5 | N5: =IF(B5="Texion Textil",0,IF(B5="Três Elos",0,IF(C5="Malha",0,IF(C5="Dublagem Cretone",'Custos insumos'!$D$23,IF(C5="Dublagem Spun",'Custos insumos'!$D$19,IF(C5="Espelhamento",0,IF(C5="Espelhamento 2x",0,IF(C5="Esp. + Pel.",0,IF(C5="Pel. + Spun",'Custos insumos'!$D$19,IF(C5="Dublagem Cretone PES",'Custos insumos'!$F$25,IF(C5="Dublagem Barreira",'Custos insumos'!$D$22,))))))))))) -> 0
B6: Aparatos | C6: Dublagem Cretone PES | E6: 1 | G6: 6.5 | H6: metro linear | I6: =G6/E6 -> 6.5 | J6: 45301 | K6: Insumos fornecidos por Tapajos | L6: =G6-M6-N6 -> 2.21 | M6: =IF(B6="Texion Textil",0,IF(C6="Malha",'Custos insumos'!$B$24,IF(C6="Dublagem Cretone",'Custos insumos'!$D$7,IF(C6="Dublagem Spun",'Custos insumos'!$D$4,IF(C6="Espelhamento",'Custos insumos'!$B$11,IF(C6="Espelhamento 2x",2*'Custos insumos'!$B$11,IF(C6="Esp. + Pel.",'Custos insumos'!$B$11,IF(C6="Pel. + Spun",'Custos insumos'!$D$4,IF(C6="Dublagem Cretone PES",'Custos insumos'!$D$7,IF(C6="Dublagem Barreira",'Custos insumos'!$D$11,IF(C6="Dublagem - MO + Filme",'Custos insumos'!$D$4,IF(C6="Dublagem Cretone HM50",'Custos insumos'!$D$26,IF(C6="Dublagem Cretone HM70",'Custos insumos'!$F$10,))))))))))))) -> 1.962 | N6: =IF(B6="Texion Textil",0,IF(B6="Três Elos",0,IF(C6="Malha",0,IF(C6="Dublagem Cretone",'Custos insumos'!$D$23,IF(C6="Dublagem Spun",'Custos insumos'!$D$19,IF(C6="Espelhamento",0,IF(C6="Espelhamento 2x",0,IF(C6="Esp. + Pel.",0,IF(C6="Pel. + Spun",'Custos insumos'!$D$19,IF(C6="Dublagem Cretone PES",'Custos insumos'!$F$25,IF(C6="Dublagem Barreira",'Custos insumos'!$D$22,))))))))))) -> 2.328
B7: Aparatos | C7: Dublagem Spun | D7: Novo | E7: 1 | G7: 6.5 | H7: metro linear | I7: =G7/E7 -> 6.5 | J7: 45301 | K7: Insumos fornecidos por Tapajos | L7: =G7-M7-N7 -> 4.4858 | M7: =IF(B7="Texion Textil",0,IF(C7="Malha",'Custos insumos'!$B$24,IF(C7="Dublagem Cretone",'Custos insumos'!$D$7,IF(C7="Dublagem Spun",'Custos insumos'!$D$4,IF(C7="Espelhamento",'Custos insumos'!$B$11,IF(C7="Espelhamento 2x",2*'Custos insumos'!$B$11,IF(C7="Esp. + Pel.",'Custos insumos'!$B$11,IF(C7="Pel. + Spun",'Custos insumos'!$D$4,IF(C7="Dublagem Cretone PES",'Custos insumos'!$D$7,IF(C7="Dublagem Barreira",'Custos insumos'!$D$11,IF(C7="Dublagem - MO + Filme",'Custos insumos'!$D$4,IF(C7="Dublagem Cretone HM50",'Custos insumos'!$D$26,IF(C7="Dublagem Cretone HM70",'Custos insumos'!$F$10,))))))))))))) -> 1.1232 | N7: =IF(B7="Texion Textil",0,IF(B7="Três Elos",0,IF(C7="Malha",0,IF(C7="Dublagem Cretone",'Custos insumos'!$D$23,IF(C7="Dublagem Spun",'Custos insumos'!$D$19,IF(C7="Espelhamento",0,IF(C7="Espelhamento 2x",0,IF(C7="Esp. + Pel.",0,IF(C7="Pel. + Spun",'Custos insumos'!$D$19,IF(C7="Dublagem Cretone PES",'Custos insumos'!$F$25,IF(C7="Dublagem Barreira",'Custos insumos'!$D$22,))))))))))) -> 0.891
B8: Aparatos | C8: Dublagem Cretone | E8: 1 | F8: 10.7 | G8: =F8+(F8*0.1) -> 11.77 | H8: metro linear | I8: =G8/E8 -> 11.77 | J8: 45301 | K8: Insumos fornecidos por Tapajos; TNT= R$ 1,42 + Filme HM20/35 = R$ 1,1 | L8: =G8-M8-N8 -> 7.48 | M8: =IF(B8="Texion Textil",0,IF(C8="Malha",'Custos insumos'!$B$24,IF(C8="Dublagem Cretone",'Custos insumos'!$D$7,IF(C8="Dublagem Spun",'Custos insumos'!$D$4,IF(C8="Espelhamento",'Custos insumos'!$B$11,IF(C8="Espelhamento 2x",2*'Custos insumos'!$B$11,IF(C8="Esp. + Pel.",'Custos insumos'!$B$11,IF(C8="Pel. + Spun",'Custos insumos'!$D$4,IF(C8="Dublagem Cretone PES",'Custos insumos'!$D$7,IF(C8="Dublagem Barreira",'Custos insumos'!$D$11,IF(C8="Dublagem - MO + Filme",'Custos insumos'!$D$4,IF(C8="Dublagem Cretone HM50",'Custos insumos'!$D$26,IF(C8="Dublagem Cretone HM70",'Custos insumos'!$F$10,))))))))))))) -> 1.962 | N8: =IF(B8="Texion Textil",0,IF(B8="Três Elos",0,IF(C8="Malha",0,IF(C8="Dublagem Cretone",'Custos insumos'!$D$23,IF(C8="Dublagem Spun",'Custos insumos'!$D$19,IF(C8="Espelhamento",0,IF(C8="Espelhamento 2x",0,IF(C8="Esp. + Pel.",0,IF(C8="Pel. + Spun",'Custos insumos'!$D$19,IF(C8="Dublagem Cretone PES",'Custos insumos'!$F$25,IF(C8="Dublagem Barreira",'Custos insumos'!$D$22,))))))))))) -> 2.328
B9: Aparatos | C9: Dublagem Spun | E9: 1 | F9: 10.7 | G9: =F9+(F9*0.1) -> 11.77 | H9: metro linear | I9: =G9/E9 -> 11.77 | J9: 45301 | K9: Insumos fornecidos por Tapajos | L9: =G9-M9-N9 -> 9.7558 | M9: =IF(B9="Texion Textil",0,IF(C9="Malha",'Custos insumos'!$B$24,IF(C9="Dublagem Cretone",'Custos insumos'!$D$7,IF(C9="Dublagem Spun",'Custos insumos'!$D$4,IF(C9="Espelhamento",'Custos insumos'!$B$11,IF(C9="Espelhamento 2x",2*'Custos insumos'!$B$11,IF(C9="Esp. + Pel.",'Custos insumos'!$B$11,IF(C9="Pel. + Spun",'Custos insumos'!$D$4,IF(C9="Dublagem Cretone PES",'Custos insumos'!$D$7,IF(C9="Dublagem Barreira",'Custos insumos'!$D$11,IF(C9="Dublagem - MO + Filme",'Custos insumos'!$D$4,IF(C9="Dublagem Cretone HM50",'Custos insumos'!$D$26,IF(C9="Dublagem Cretone HM70",'Custos insumos'!$F$10,))))))))))))) -> 1.1232 | N9: =IF(B9="Texion Textil",0,IF(B9="Três Elos",0,IF(C9="Malha",0,IF(C9="Dublagem Cretone",'Custos insumos'!$D$23,IF(C9="Dublagem Spun",'Custos insumos'!$D$19,IF(C9="Espelhamento",0,IF(C9="Espelhamento 2x",0,IF(C9="Esp. + Pel.",0,IF(C9="Pel. + Spun",'Custos insumos'!$D$19,IF(C9="Dublagem Cretone PES",'Custos insumos'!$F$25,IF(C9="Dublagem Barreira",'Custos insumos'!$D$22,))))))))))) -> 0.891
B10: Aparatos | C10: Espelhamento | E10: 1 | F10: 6.7 | G10: =F10+(F10*0.1) -> 7.37 | H10: metro linear | I10: =G10/E10 -> 7.37 | J10: 45301 | K10: Insumos fornecidos por Tapajos | L10: =G10-M10-N10 -> 6.3114997 | M10: =IF(B10="Texion Textil",0,IF(C10="Malha",'Custos insumos'!$B$24,IF(C10="Dublagem Cretone",'Custos insumos'!$D$7,IF(C10="Dublagem Spun",'Custos insumos'!$D$4,IF(C10="Espelhamento",'Custos insumos'!$B$11,IF(C10="Espelhamento 2x",2*'Custos insumos'!$B$11,IF(C10="Esp. + Pel.",'Custos insumos'!$B$11,IF(C10="Pel. + Spun",'Custos insumos'!$D$4,IF(C10="Dublagem Cretone PES",'Custos insumos'!$D$7,IF(C10="Dublagem Barreira",'Custos insumos'!$D$11,IF(C10="Dublagem - MO + Filme",'Custos insumos'!$D$4,IF(C10="Dublagem Cretone HM50",'Custos insumos'!$D$26,IF(C10="Dublagem Cretone HM70",'Custos insumos'!$F$10,))))))))))))) -> 1.0585003 | N10: =IF(B10="Texion Textil",0,IF(B10="Três Elos",0,IF(C10="Malha",0,IF(C10="Dublagem Cretone",'Custos insumos'!$D$23,IF(C10="Dublagem Spun",'Custos insumos'!$D$19,IF(C10="Espelhamento",0,IF(C10="Espelhamento 2x",0,IF(C10="Esp. + Pel.",0,IF(C10="Pel. + Spun",'Custos insumos'!$D$19,IF(C10="Dublagem Cretone PES",'Custos insumos'!$F$25,IF(C10="Dublagem Barreira",'Custos insumos'!$D$22,))))))))))) -> 0
B11: Bergon | C11: Felpagem | D11: 12221 e 12179 | E11: 2 | F11: 0.5 | G11: 0.5 | H11: metro linear | I11: =G11/E11 -> 0.25 | J11: 45301 | L11: =G11-M11-N11 -> 0.5 | M11: =IF(B11="Texion Textil",0,IF(C11="Malha",'Custos insumos'!$B$24,IF(C11="Dublagem Cretone",'Custos insumos'!$D$7,IF(C11="Dublagem Spun",'Custos insumos'!$D$4,IF(C11="Espelhamento",'Custos insumos'!$B$11,IF(C11="Espelhamento 2x",2*'Custos insumos'!$B$11,IF(C11="Esp. + Pel.",'Custos insumos'!$B$11,IF(C11="Pel. + Spun",'Custos insumos'!$D$4,IF(C11="Dublagem Cretone PES",'Custos insumos'!$D$7,IF(C11="Dublagem Barreira",'Custos insumos'!$D$11,IF(C11="Dublagem - MO + Filme",'Custos insumos'!$D$4,IF(C11="Dublagem Cretone HM50",'Custos insumos'!$D$26,IF(C11="Dublagem Cretone HM70",'Custos insumos'!$F$10,))))))))))))) -> 0 | N11: =IF(B11="Texion Textil",0,IF(B11="Três Elos",0,IF(C11="Malha",0,IF(C11="Dublagem Cretone",'Custos insumos'!$D$23,IF(C11="Dublagem Spun",'Custos insumos'!$D$19,IF(C11="Espelhamento",0,IF(C11="Espelhamento 2x",0,IF(C11="Esp. + Pel.",0,IF(C11="Pel. + Spun",'Custos insumos'!$D$19,IF(C11="Dublagem Cretone PES",'Custos insumos'!$F$25,IF(C11="Dublagem Barreira",'Custos insumos'!$D$22,))))))))))) -> 0
A12: ok | B12: Bergon | C12: Felpagem | D12: 12142 | E12: 2 | F12: 0.35 | G12: 0.35 | H12: metro linear | I12: =G12/E12 -> 0.175 | J12: 45301 | L12: =G12-M12-N12 -> 0.35 | M12: =IF(B12="Texion Textil",0,IF(C12="Malha",'Custos insumos'!$B$24,IF(C12="Dublagem Cretone",'Custos insumos'!$D$7,IF(C12="Dublagem Spun",'Custos insumos'!$D$4,IF(C12="Espelhamento",'Custos insumos'!$B$11,IF(C12="Espelhamento 2x",2*'Custos insumos'!$B$11,IF(C12="Esp. + Pel.",'Custos insumos'!$B$11,IF(C12="Pel. + Spun",'Custos insumos'!$D$4,IF(C12="Dublagem Cretone PES",'Custos insumos'!$D$7,IF(C12="Dublagem Barreira",'Custos insumos'!$D$11,IF(C12="Dublagem - MO + Filme",'Custos insumos'!$D$4,IF(C12="Dublagem Cretone HM50",'Custos insumos'!$D$26,IF(C12="Dublagem Cretone HM70",'Custos insumos'!$F$10,))))))))))))) -> 0 | N12: =IF(B12="Texion Textil",0,IF(B12="Três Elos",0,IF(C12="Malha",0,IF(C12="Dublagem Cretone",'Custos insumos'!$D$23,IF(C12="Dublagem Spun",'Custos insumos'!$D$19,IF(C12="Espelhamento",0,IF(C12="Espelhamento 2x",0,IF(C12="Esp. + Pel.",0,IF(C12="Pel. + Spun",'Custos insumos'!$D$19,IF(C12="Dublagem Cretone PES",'Custos insumos'!$F$25,IF(C12="Dublagem Barreira",'Custos insumos'!$D$22,))))))))))) -> 0
A13: ok | B13: Bergon | C13: Peletização | E13: 1 | G13: 0.45 | H13: metro linear | I13: =G13/E13 -> 0.45 | J13: 45301 | L13: =G13-M13-N13 -> 0.45 | M13: =IF(B13="Texion Textil",0,IF(C13="Malha",'Custos insumos'!$B$24,IF(C13="Dublagem Cretone",'Custos insumos'!$D$7,IF(C13="Dublagem Spun",'Custos insumos'!$D$4,IF(C13="Espelhamento",'Custos insumos'!$B$11,IF(C13="Espelhamento 2x",2*'Custos insumos'!$B$11,IF(C13="Esp. + Pel.",'Custos insumos'!$B$11,IF(C13="Pel. + Spun",'Custos insumos'!$D$4,IF(C13="Dublagem Cretone PES",'Custos insumos'!$D$7,IF(C13="Dublagem Barreira",'Custos insumos'!$D$11,IF(C13="Dublagem - MO + Filme",'Custos insumos'!$D$4,IF(C13="Dublagem Cretone HM50",'Custos insumos'!$D$26,IF(C13="Dublagem Cretone HM70",'Custos insumos'!$F$10,))))))))))))) -> 0 | N13: =IF(B13="Texion Textil",0,IF(B13="Três Elos",0,IF(C13="Malha",0,IF(C13="Dublagem Cretone",'Custos insumos'!$D$23,IF(C13="Dublagem Spun",'Custos insumos'!$D$19,IF(C13="Espelhamento",0,IF(C13="Espelhamento 2x",0,IF(C13="Esp. + Pel.",0,IF(C13="Pel. + Spun",'Custos insumos'!$D$19,IF(C13="Dublagem Cretone PES",'Custos insumos'!$F$25,IF(C13="Dublagem Barreira",'Custos insumos'!$D$22,))))))))))) -> 0
A14: ok | B14: Bergon | C14: Calandra | E14: 1 | G14: 0.65 | H14: metro linear | I14: =G14/E14 -> 0.65 | J14: 45301 | L14: =G14-M14-N14 -> 0.65 | M14: =IF(B14="Texion Textil",0,IF(C14="Malha",'Custos insumos'!$B$24,IF(C14="Dublagem Cretone",'Custos insumos'!$D$7,IF(C14="Dublagem Spun",'Custos insumos'!$D$4,IF(C14="Espelhamento",'Custos insumos'!$B$11,IF(C14="Espelhamento 2x",2*'Custos insumos'!$B$11,IF(C14="Esp. + Pel.",'Custos insumos'!$B$11,IF(C14="Pel. + Spun",'Custos insumos'!$D$4,IF(C14="Dublagem Cretone PES",'Custos insumos'!$D$7,IF(C14="Dublagem Barreira",'Custos insumos'!$D$11,IF(C14="Dublagem - MO + Filme",'Custos insumos'!$D$4,IF(C14="Dublagem Cretone HM50",'Custos insumos'!$D$26,IF(C14="Dublagem Cretone HM70",'Custos insumos'!$F$10,))))))))))))) -> 0 | N14: =IF(B14="Texion Textil",0,IF(B14="Três Elos",0,IF(C14="Malha",0,IF(C14="Dublagem Cretone",'Custos insumos'!$D$23,IF(C14="Dublagem Spun",'Custos insumos'!$D$19,IF(C14="Espelhamento",0,IF(C14="Espelhamento 2x",0,IF(C14="Esp. + Pel.",0,IF(C14="Pel. + Spun",'Custos insumos'!$D$19,IF(C14="Dublagem Cretone PES",'Custos insumos'!$F$25,IF(C14="Dublagem Barreira",'Custos insumos'!$D$22,))))))))))) -> 0
A15: ok | B15: Bergon | C15: Espelhamento - MO | E15: 1 | G15: 1.15 | H15: metro linear | I15: =G15/E15 -> 1.15 | J15: 45301 | K15: Mão de obra | L15: =G15-M15-N15 -> 1.15 | M15: =IF(B15="Texion Textil",0,IF(C15="Malha",'Custos insumos'!$B$24,IF(C15="Dublagem Cretone",'Custos insumos'!$D$7,IF(C15="Dublagem Spun",'Custos insumos'!$D$4,IF(C15="Espelhamento",'Custos insumos'!$B$11,IF(C15="Espelhamento 2x",2*'Custos insumos'!$B$11,IF(C15="Esp. + Pel.",'Custos insumos'!$B$11,IF(C15="Pel. + Spun",'Custos insumos'!$D$4,IF(C15="Dublagem Cretone PES",'Custos insumos'!$D$7,IF(C15="Dublagem Barreira",'Custos insumos'!$D$11,IF(C15="Dublagem - MO + Filme",'Custos insumos'!$D$4,IF(C15="Dublagem Cretone HM50",'Custos insumos'!$D$26,IF(C15="Dublagem Cretone HM70",'Custos insumos'!$F$10,))))))))))))) -> 0 | N15: =IF(B15="Texion Textil",0,IF(B15="Três Elos",0,IF(C15="Malha",0,IF(C15="Dublagem Cretone",'Custos insumos'!$D$23,IF(C15="Dublagem Spun",'Custos insumos'!$D$19,IF(C15="Espelhamento",0,IF(C15="Espelhamento 2x",0,IF(C15="Esp. + Pel.",0,IF(C15="Pel. + Spun",'Custos insumos'!$D$19,IF(C15="Dublagem Cretone PES",'Custos insumos'!$F$25,IF(C15="Dublagem Barreira",'Custos insumos'!$D$22,))))))))))) -> 0
A16: ok | B16: Bergon | C16: Espelhamento | E16: 1 | G16: 2.35 | H16: metro linear | I16: =G16/E16 -> 2.35 | J16: 45301 | K16: Mão de obra e insumos | L16: =G16-M16-N16 -> 1.2914997 | M16: =IF(B16="Texion Textil",0,IF(C16="Malha",'Custos insumos'!$B$24,IF(C16="Dublagem Cretone",'Custos insumos'!$D$7,IF(C16="Dublagem Spun",'Custos insumos'!$D$4,IF(C16="Espelhamento",'Custos insumos'!$B$11,IF(C16="Espelhamento 2x",2*'Custos insumos'!$B$11,IF(C16="Esp. + Pel.",'Custos insumos'!$B$11,IF(C16="Pel. + Spun",'Custos insumos'!$D$4,IF(C16="Dublagem Cretone PES",'Custos insumos'!$D$7,IF(C16="Dublagem Barreira",'Custos insumos'!$D$11,IF(C16="Dublagem - MO + Filme",'Custos insumos'!$D$4,IF(C16="Dublagem Cretone HM50",'Custos insumos'!$D$26,IF(C16="Dublagem Cretone HM70",'Custos insumos'!$F$10,))))))))))))) -> 1.0585003 | N16: =IF(B16="Texion Textil",0,IF(B16="Três Elos",0,IF(C16="Malha",0,IF(C16="Dublagem Cretone",'Custos insumos'!$D$23,IF(C16="Dublagem Spun",'Custos insumos'!$D$19,IF(C16="Espelhamento",0,IF(C16="Espelhamento 2x",0,IF(C16="Esp. + Pel.",0,IF(C16="Pel. + Spun",'Custos insumos'!$D$19,IF(C16="Dublagem Cretone PES",'Custos insumos'!$F$25,IF(C16="Dublagem Barreira",'Custos insumos'!$D$22,))))))))))) -> 0
A17: ok | B17: Bergon | C17: Dublagem Spun - MO | E17: 1 | G17: 1.15 | H17: metro linear | I17: =G17/E17 -> 1.15 | J17: 45301 | K17: Mão de obra | L17: =G17-M17-N17 -> 1.15 | M17: =IF(B17="Texion Textil",0,IF(C17="Malha",'Custos insumos'!$B$24,IF(C17="Dublagem Cretone",'Custos insumos'!$D$7,IF(C17="Dublagem Spun",'Custos insumos'!$D$4,IF(C17="Espelhamento",'Custos insumos'!$B$11,IF(C17="Espelhamento 2x",2*'Custos insumos'!$B$11,IF(C17="Esp. + Pel.",'Custos insumos'!$B$11,IF(C17="Pel. + Spun",'Custos insumos'!$D$4,IF(C17="Dublagem Cretone PES",'Custos insumos'!$D$7,IF(C17="Dublagem Barreira",'Custos insumos'!$D$11,IF(C17="Dublagem - MO + Filme",'Custos insumos'!$D$4,IF(C17="Dublagem Cretone HM50",'Custos insumos'!$D$26,IF(C17="Dublagem Cretone HM70",'Custos insumos'!$F$10,))))))))))))) -> 0 | N17: =IF(B17="Texion Textil",0,IF(B17="Três Elos",0,IF(C17="Malha",0,IF(C17="Dublagem Cretone",'Custos insumos'!$D$23,IF(C17="Dublagem Spun",'Custos insumos'!$D$19,IF(C17="Espelhamento",0,IF(C17="Espelhamento 2x",0,IF(C17="Esp. + Pel.",0,IF(C17="Pel. + Spun",'Custos insumos'!$D$19,IF(C17="Dublagem Cretone PES",'Custos insumos'!$F$25,IF(C17="Dublagem Barreira",'Custos insumos'!$D$22,))))))))))) -> 0
A18: ok | B18: Bergon | C18: Dublagem Spun | E18: 1 | G18: 4.5 | H18: metro linear | I18: =G18/E18 -> 4.5 | J18: 45301 | K18: Mão de obra e insumos | L18: =G18-M18-N18 -> 2.4858 | M18: =IF(B18="Texion Textil",0,IF(C18="Malha",'Custos insumos'!$B$24,IF(C18="Dublagem Cretone",'Custos insumos'!$D$7,IF(C18="Dublagem Spun",'Custos insumos'!$D$4,IF(C18="Espelhamento",'Custos insumos'!$B$11,IF(C18="Espelhamento 2x",2*'Custos insumos'!$B$11,IF(C18="Esp. + Pel.",'Custos insumos'!$B$11,IF(C18="Pel. + Spun",'Custos insumos'!$D$4,IF(C18="Dublagem Cretone PES",'Custos insumos'!$D$7,IF(C18="Dublagem Barreira",'Custos insumos'!$D$11,IF(C18="Dublagem - MO + Filme",'Custos insumos'!$D$4,IF(C18="Dublagem Cretone HM50",'Custos insumos'!$D$26,IF(C18="Dublagem Cretone HM70",'Custos insumos'!$F$10,))))))))))))) -> 1.1232 | N18: =IF(B18="Texion Textil",0,IF(B18="Três Elos",0,IF(C18="Malha",0,IF(C18="Dublagem Cretone",'Custos insumos'!$D$23,IF(C18="Dublagem Spun",'Custos insumos'!$D$19,IF(C18="Espelhamento",0,IF(C18="Espelhamento 2x",0,IF(C18="Esp. + Pel.",0,IF(C18="Pel. + Spun",'Custos insumos'!$D$19,IF(C18="Dublagem Cretone PES",'Custos insumos'!$F$25,IF(C18="Dublagem Barreira",'Custos insumos'!$D$22,))))))))))) -> 0.891
A19: ok | B19: Bergon | C19: Dublagem Cretone - MO | E19: 1 | G19: 1.15 | H19: metro linear | I19: =G19/E19 -> 1.15 | J19: 45301 | K19: Mão de obra | L19: =G19-M19-N19 -> 1.15 | M19: =IF(B19="Texion Textil",0,IF(C19="Malha",'Custos insumos'!$B$24,IF(C19="Dublagem Cretone",'Custos insumos'!$D$7,IF(C19="Dublagem Spun",'Custos insumos'!$D$4,IF(C19="Espelhamento",'Custos insumos'!$B$11,IF(C19="Espelhamento 2x",2*'Custos insumos'!$B$11,IF(C19="Esp. + Pel.",'Custos insumos'!$B$11,IF(C19="Pel. + Spun",'Custos insumos'!$D$4,IF(C19="Dublagem Cretone PES",'Custos insumos'!$D$7,IF(C19="Dublagem Barreira",'Custos insumos'!$D$11,IF(C19="Dublagem - MO + Filme",'Custos insumos'!$D$4,IF(C19="Dublagem Cretone HM50",'Custos insumos'!$D$26,IF(C19="Dublagem Cretone HM70",'Custos insumos'!$F$10,))))))))))))) -> 0 | N19: =IF(B19="Texion Textil",0,IF(B19="Três Elos",0,IF(C19="Malha",0,IF(C19="Dublagem Cretone",'Custos insumos'!$D$23,IF(C19="Dublagem Spun",'Custos insumos'!$D$19,IF(C19="Espelhamento",0,IF(C19="Espelhamento 2x",0,IF(C19="Esp. + Pel.",0,IF(C19="Pel. + Spun",'Custos insumos'!$D$19,IF(C19="Dublagem Cretone PES",'Custos insumos'!$F$25,IF(C19="Dublagem Barreira",'Custos insumos'!$D$22,))))))))))) -> 0
A20: ok | B20: By For man | C20: Felpagem | E20: 1 | G20: 1.1 | H20: metro linear | I20: =G20/E20 -> 1.1 | L20: =G20-M20-N20 -> 1.1 | M20: =IF(B20="Texion Textil",0,IF(C20="Malha",'Custos insumos'!$B$24,IF(C20="Dublagem Cretone",'Custos insumos'!$D$7,IF(C20="Dublagem Spun",'Custos insumos'!$D$4,IF(C20="Espelhamento",'Custos insumos'!$B$11,IF(C20="Espelhamento 2x",2*'Custos insumos'!$B$11,IF(C20="Esp. + Pel.",'Custos insumos'!$B$11,IF(C20="Pel. + Spun",'Custos insumos'!$D$4,IF(C20="Dublagem Cretone PES",'Custos insumos'!$D$7,IF(C20="Dublagem Barreira",'Custos insumos'!$D$11,IF(C20="Dublagem - MO + Filme",'Custos insumos'!$D$4,IF(C20="Dublagem Cretone HM50",'Custos insumos'!$D$26,IF(C20="Dublagem Cretone HM70",'Custos insumos'!$F$10,))))))))))))) -> 0 | N20: =IF(B20="Texion Textil",0,IF(B20="Três Elos",0,IF(C20="Malha",0,IF(C20="Dublagem Cretone",'Custos insumos'!$D$23,IF(C20="Dublagem Spun",'Custos insumos'!$D$19,IF(C20="Espelhamento",0,IF(C20="Espelhamento 2x",0,IF(C20="Esp. + Pel.",0,IF(C20="Pel. + Spun",'Custos insumos'!$D$19,IF(C20="Dublagem Cretone PES",'Custos insumos'!$F$25,IF(C20="Dublagem Barreira",'Custos insumos'!$D$22,))))))))))) -> 0
B21: Calmart | C21: Peletização | E21: 1 | F21: 0.6 | G21: 0.65 | H21: metro linear | I21: =G21/E21 -> 0.65 | J21: 45301 | L21: =G21-M21-N21 -> 0.65 | M21: =IF(B21="Texion Textil",0,IF(C21="Malha",'Custos insumos'!$B$24,IF(C21="Dublagem Cretone",'Custos insumos'!$D$7,IF(C21="Dublagem Spun",'Custos insumos'!$D$4,IF(C21="Espelhamento",'Custos insumos'!$B$11,IF(C21="Espelhamento 2x",2*'Custos insumos'!$B$11,IF(C21="Esp. + Pel.",'Custos insumos'!$B$11,IF(C21="Pel. + Spun",'Custos insumos'!$D$4,IF(C21="Dublagem Cretone PES",'Custos insumos'!$D$7,IF(C21="Dublagem Barreira",'Custos insumos'!$D$11,IF(C21="Dublagem - MO + Filme",'Custos insumos'!$D$4,IF(C21="Dublagem Cretone HM50",'Custos insumos'!$D$26,IF(C21="Dublagem Cretone HM70",'Custos insumos'!$F$10,))))))))))))) -> 0 | N21: =IF(B21="Texion Textil",0,IF(B21="Três Elos",0,IF(C21="Malha",0,IF(C21="Dublagem Cretone",'Custos insumos'!$D$23,IF(C21="Dublagem Spun",'Custos insumos'!$D$19,IF(C21="Espelhamento",0,IF(C21="Espelhamento 2x",0,IF(C21="Esp. + Pel.",0,IF(C21="Pel. + Spun",'Custos insumos'!$D$19,IF(C21="Dublagem Cretone PES",'Custos insumos'!$F$25,IF(C21="Dublagem Barreira",'Custos insumos'!$D$22,))))))))))) -> 0
A22: ok | B22: Calmart | C22: Dublagem Cretone - MO | E22: 1 | F22: 2.14 | G22: =1.19+1.15 -> 2.34 | H22: metro linear | I22: =G22/E22 -> 2.34 | J22: 45301 | K22: Mão de obra e filme | L22: =G22-M22-N22 -> 0.378 | M22: ='Custos insumos'!D7 -> 1.962 | N22: 0
A23: ok | B23: Chumbrecas/MX72/Tavares e Filhos | C23: Felpagem | E23: 3 | F23: 1 | G23: 1.1 | H23: metro linear | I23: =G23/E23 -> 0.36666667 | J23: 45301 | L23: =G23-M23-N23 -> 1.1 | M23: =IF(B23="Texion Textil",0,IF(C23="Malha",'Custos insumos'!$B$24,IF(C23="Dublagem Cretone",'Custos insumos'!$D$7,IF(C23="Dublagem Spun",'Custos insumos'!$D$4,IF(C23="Espelhamento",'Custos insumos'!$B$11,IF(C23="Espelhamento 2x",2*'Custos insumos'!$B$11,IF(C23="Esp. + Pel.",'Custos insumos'!$B$11,IF(C23="Pel. + Spun",'Custos insumos'!$D$4,IF(C23="Dublagem Cretone PES",'Custos insumos'!$D$7,IF(C23="Dublagem Barreira",'Custos insumos'!$D$11,IF(C23="Dublagem - MO + Filme",'Custos insumos'!$D$4,IF(C23="Dublagem Cretone HM50",'Custos insumos'!$D$26,IF(C23="Dublagem Cretone HM70",'Custos insumos'!$F$10,))))))))))))) -> 0 | N23: =IF(B23="Texion Textil",0,IF(B23="Três Elos",0,IF(C23="Malha",0,IF(C23="Dublagem Cretone",'Custos insumos'!$D$23,IF(C23="Dublagem Spun",'Custos insumos'!$D$19,IF(C23="Espelhamento",0,IF(C23="Espelhamento 2x",0,IF(C23="Esp. + Pel.",0,IF(C23="Pel. + Spun",'Custos insumos'!$D$19,IF(C23="Dublagem Cretone PES",'Custos insumos'!$F$25,IF(C23="Dublagem Barreira",'Custos insumos'!$D$22,))))))))))) -> 0
B24: Coleção Textil | C24: Peletização | E24: 1 | F24: 0.5 | G24: 0.75 | H24: metro linear | I24: =G24/E24 -> 0.75 | J24: 45301 | L24: 0.75 | M24: =IF(B24="Texion Textil",0,IF(C24="Malha",'Custos insumos'!$B$24,IF(C24="Dublagem Cretone",'Custos insumos'!$D$7,IF(C24="Dublagem Spun",'Custos insumos'!$D$4,IF(C24="Espelhamento",'Custos insumos'!$B$11,IF(C24="Espelhamento 2x",2*'Custos insumos'!$B$11,IF(C24="Esp. + Pel.",'Custos insumos'!$B$11,IF(C24="Pel. + Spun",'Custos insumos'!$D$4,IF(C24="Dublagem Cretone PES",'Custos insumos'!$D$7,IF(C24="Dublagem Barreira",'Custos insumos'!$D$11,IF(C24="Dublagem - MO + Filme",'Custos insumos'!$D$4,IF(C24="Dublagem Cretone HM50",'Custos insumos'!$D$26,IF(C24="Dublagem Cretone HM70",'Custos insumos'!$F$10,))))))))))))) -> 0 | N24: =IF(B24="Texion Textil",0,IF(B24="Três Elos",0,IF(C24="Malha",0,IF(C24="Dublagem Cretone",'Custos insumos'!$D$23,IF(C24="Dublagem Spun",'Custos insumos'!$D$19,IF(C24="Espelhamento",0,IF(C24="Espelhamento 2x",0,IF(C24="Esp. + Pel.",0,IF(C24="Pel. + Spun",'Custos insumos'!$D$19,IF(C24="Dublagem Cretone PES",'Custos insumos'!$F$25,IF(C24="Dublagem Barreira",'Custos insumos'!$D$22,))))))))))) -> 0
B25: Coleção Textil | C25: Peletização | D25: Duas passadas | E25: 2 | F25: 0.5 | G25: 1.25 | H25: metro linear | I25: =G25/E25 -> 0.625 | J25: 45301 | L25: =G25-M25-N25 -> 1.25 | M25: =IF(B25="Texion Textil",0,IF(C25="Malha",'Custos insumos'!$B$24,IF(C25="Dublagem Cretone",'Custos insumos'!$D$7,IF(C25="Dublagem Spun",'Custos insumos'!$D$4,IF(C25="Espelhamento",'Custos insumos'!$B$11,IF(C25="Espelhamento 2x",2*'Custos insumos'!$B$11,IF(C25="Esp. + Pel.",'Custos insumos'!$B$11,IF(C25="Pel. + Spun",'Custos insumos'!$D$4,IF(C25="Dublagem Cretone PES",'Custos insumos'!$D$7,IF(C25="Dublagem Barreira",'Custos insumos'!$D$11,IF(C25="Dublagem - MO + Filme",'Custos insumos'!$D$4,IF(C25="Dublagem Cretone HM50",'Custos insumos'!$D$26,IF(C25="Dublagem Cretone HM70",'Custos insumos'!$F$10,))))))))))))) -> 0 | N25: =IF(B25="Texion Textil",0,IF(B25="Três Elos",0,IF(C25="Malha",0,IF(C25="Dublagem Cretone",'Custos insumos'!$D$23,IF(C25="Dublagem Spun",'Custos insumos'!$D$19,IF(C25="Espelhamento",0,IF(C25="Espelhamento 2x",0,IF(C25="Esp. + Pel.",0,IF(C25="Pel. + Spun",'Custos insumos'!$D$19,IF(C25="Dublagem Cretone PES",'Custos insumos'!$F$25,IF(C25="Dublagem Barreira",'Custos insumos'!$D$22,))))))))))) -> 0
B26: Compomax | C26: Felpagem | E26: 3 | F26: 0.3 | G26: 0.4 | H26: metro linear | I26: =G26/E26 -> 0.13333333 | J26: 45301 | L26: =G26-M26-N26 -> 0.4 | M26: =IF(B26="Texion Textil",0,IF(C26="Malha",'Custos insumos'!$B$24,IF(C26="Dublagem Cretone",'Custos insumos'!$D$7,IF(C26="Dublagem Spun",'Custos insumos'!$D$4,IF(C26="Espelhamento",'Custos insumos'!$B$11,IF(C26="Espelhamento 2x",2*'Custos insumos'!$B$11,IF(C26="Esp. + Pel.",'Custos insumos'!$B$11,IF(C26="Pel. + Spun",'Custos insumos'!$D$4,IF(C26="Dublagem Cretone PES",'Custos insumos'!$D$7,IF(C26="Dublagem Barreira",'Custos insumos'!$D$11,IF(C26="Dublagem - MO + Filme",'Custos insumos'!$D$4,IF(C26="Dublagem Cretone HM50",'Custos insumos'!$D$26,IF(C26="Dublagem Cretone HM70",'Custos insumos'!$F$10,))))))))))))) -> 0 | N26: =IF(B26="Texion Textil",0,IF(B26="Três Elos",0,IF(C26="Malha",0,IF(C26="Dublagem Cretone",'Custos insumos'!$D$23,IF(C26="Dublagem Spun",'Custos insumos'!$D$19,IF(C26="Espelhamento",0,IF(C26="Espelhamento 2x",0,IF(C26="Esp. + Pel.",0,IF(C26="Pel. + Spun",'Custos insumos'!$D$19,IF(C26="Dublagem Cretone PES",'Custos insumos'!$F$25,IF(C26="Dublagem Barreira",'Custos insumos'!$D$22,))))))))))) -> 0
B27: Covolan Benefic. | C27: Peletização | E27: 1 | F27: 0.5 | G27: 0.55 | H27: metro linear | I27: =G27/E27 -> 0.55 | J27: 45301 | L27: =G27-M27-N27 -> 0.55 | M27: =IF(B27="Texion Textil",0,IF(C27="Malha",'Custos insumos'!$B$24,IF(C27="Dublagem Cretone",'Custos insumos'!$D$7,IF(C27="Dublagem Spun",'Custos insumos'!$D$4,IF(C27="Espelhamento",'Custos insumos'!$B$11,IF(C27="Espelhamento 2x",2*'Custos insumos'!$B$11,IF(C27="Esp. + Pel.",'Custos insumos'!$B$11,IF(C27="Pel. + Spun",'Custos insumos'!$D$4,IF(C27="Dublagem Cretone PES",'Custos insumos'!$D$7,IF(C27="Dublagem Barreira",'Custos insumos'!$D$11,IF(C27="Dublagem - MO + Filme",'Custos insumos'!$D$4,IF(C27="Dublagem Cretone HM50",'Custos insumos'!$D$26,IF(C27="Dublagem Cretone HM70",'Custos insumos'!$F$10,))))))))))))) -> 0 | N27: =IF(B27="Texion Textil",0,IF(B27="Três Elos",0,IF(C27="Malha",0,IF(C27="Dublagem Cretone",'Custos insumos'!$D$23,IF(C27="Dublagem Spun",'Custos insumos'!$D$19,IF(C27="Espelhamento",0,IF(C27="Espelhamento 2x",0,IF(C27="Esp. + Pel.",0,IF(C27="Pel. + Spun",'Custos insumos'!$D$19,IF(C27="Dublagem Cretone PES",'Custos insumos'!$F$25,IF(C27="Dublagem Barreira",'Custos insumos'!$D$22,))))))))))) -> 0
B28: Covolan Benefic. | C28: Malha | E28: 1 | F28: 18.9 | G28: 20.9 | H28: kg | I28: =G28/E28 -> 20.9 | J28: 45301 | L28: =G28-M28-N28 -> 8.4 | M28: =IF(B28="Texion Textil",0,IF(C28="Malha",'Custos insumos'!$B$24,IF(C28="Dublagem Cretone",'Custos insumos'!$D$7,IF(C28="Dublagem Spun",'Custos insumos'!$D$4,IF(C28="Espelhamento",'Custos insumos'!$B$11,IF(C28="Espelhamento 2x",2*'Custos insumos'!$B$11,IF(C28="Esp. + Pel.",'Custos insumos'!$B$11,IF(C28="Pel. + Spun",'Custos insumos'!$D$4,IF(C28="Dublagem Cretone PES",'Custos insumos'!$D$7,IF(C28="Dublagem Barreira",'Custos insumos'!$D$11,IF(C28="Dublagem - MO + Filme",'Custos insumos'!$D$4,IF(C28="Dublagem Cretone HM50",'Custos insumos'!$D$26,IF(C28="Dublagem Cretone HM70",'Custos insumos'!$F$10,))))))))))))) -> 12.5 | N28: =IF(B28="Texion Textil",0,IF(B28="Três Elos",0,IF(C28="Malha",0,IF(C28="Dublagem Cretone",'Custos insumos'!$D$23,IF(C28="Dublagem Spun",'Custos insumos'!$D$19,IF(C28="Espelhamento",0,IF(C28="Espelhamento 2x",0,IF(C28="Esp. + Pel.",0,IF(C28="Pel. + Spun",'Custos insumos'!$D$19,IF(C28="Dublagem Cretone PES",'Custos insumos'!$F$25,IF(C28="Dublagem Barreira",'Custos insumos'!$D$22,))))))))))) -> 0
B29: DB RAINBOW | C29: Dublagem | E29: 1 | F29: 0.86 | G29: - | H29: metro linear | I29: =G29/E29 -> #VALUE! | J29: 45301 | L29: =G29-M29-N29 -> #VALUE! | M29: =IF(B29="Texion Textil",0,IF(C29="Malha",'Custos insumos'!$B$24,IF(C29="Dublagem Cretone",'Custos insumos'!$D$7,IF(C29="Dublagem Spun",'Custos insumos'!$D$4,IF(C29="Espelhamento",'Custos insumos'!$B$11,IF(C29="Espelhamento 2x",2*'Custos insumos'!$B$11,IF(C29="Esp. + Pel.",'Custos insumos'!$B$11,IF(C29="Pel. + Spun",'Custos insumos'!$D$4,IF(C29="Dublagem Cretone PES",'Custos insumos'!$D$7,IF(C29="Dublagem Barreira",'Custos insumos'!$D$11,IF(C29="Dublagem - MO + Filme",'Custos insumos'!$D$4,IF(C29="Dublagem Cretone HM50",'Custos insumos'!$D$26,IF(C29="Dublagem Cretone HM70",'Custos insumos'!$F$10,))))))))))))) -> 0 | N29: =IF(B29="Texion Textil",0,IF(B29="Três Elos",0,IF(C29="Malha",0,IF(C29="Dublagem Cretone",'Custos insumos'!$D$23,IF(C29="Dublagem Spun",'Custos insumos'!$D$19,IF(C29="Espelhamento",0,IF(C29="Espelhamento 2x",0,IF(C29="Esp. + Pel.",0,IF(C29="Pel. + Spun",'Custos insumos'!$D$19,IF(C29="Dublagem Cretone PES",'Custos insumos'!$F$25,IF(C29="Dublagem Barreira",'Custos insumos'!$D$22,))))))))))) -> 0
A30: ok | B30: DB RAINBOW | C30: Felpagem | E30: 1 | F30: 0.34 | G30: - | H30: metro linear | I30: =G30/E30 -> #VALUE! | J30: 45301 | L30: =G30-M30-N30 -> #VALUE! | M30: =IF(B30="Texion Textil",0,IF(C30="Malha",'Custos insumos'!$B$24,IF(C30="Dublagem Cretone",'Custos insumos'!$D$7,IF(C30="Dublagem Spun",'Custos insumos'!$D$4,IF(C30="Espelhamento",'Custos insumos'!$B$11,IF(C30="Espelhamento 2x",2*'Custos insumos'!$B$11,IF(C30="Esp. + Pel.",'Custos insumos'!$B$11,IF(C30="Pel. + Spun",'Custos insumos'!$D$4,IF(C30="Dublagem Cretone PES",'Custos insumos'!$D$7,IF(C30="Dublagem Barreira",'Custos insumos'!$D$11,IF(C30="Dublagem - MO + Filme",'Custos insumos'!$D$4,IF(C30="Dublagem Cretone HM50",'Custos insumos'!$D$26,IF(C30="Dublagem Cretone HM70",'Custos insumos'!$F$10,))))))))))))) -> 0 | N30: =IF(B30="Texion Textil",0,IF(B30="Três Elos",0,IF(C30="Malha",0,IF(C30="Dublagem Cretone",'Custos insumos'!$D$23,IF(C30="Dublagem Spun",'Custos insumos'!$D$19,IF(C30="Espelhamento",0,IF(C30="Espelhamento 2x",0,IF(C30="Esp. + Pel.",0,IF(C30="Pel. + Spun",'Custos insumos'!$D$19,IF(C30="Dublagem Cretone PES",'Custos insumos'!$F$25,IF(C30="Dublagem Barreira",'Custos insumos'!$D$22,))))))))))) -> 0
A31: ok | B31: DB RAINBOW | C31: Peletização | E31: 1 | F31: 0.34 | G31: - | H31: metro linear | I31: =G31/E31 -> #VALUE! | J31: 45301 | L31: =G31-M31-N31 -> #VALUE! | M31: =IF(B31="Texion Textil",0,IF(C31="Malha",'Custos insumos'!$B$24,IF(C31="Dublagem Cretone",'Custos insumos'!$D$7,IF(C31="Dublagem Spun",'Custos insumos'!$D$4,IF(C31="Espelhamento",'Custos insumos'!$B$11,IF(C31="Espelhamento 2x",2*'Custos insumos'!$B$11,IF(C31="Esp. + Pel.",'Custos insumos'!$B$11,IF(C31="Pel. + Spun",'Custos insumos'!$D$4,IF(C31="Dublagem Cretone PES",'Custos insumos'!$D$7,IF(C31="Dublagem Barreira",'Custos insumos'!$D$11,IF(C31="Dublagem - MO + Filme",'Custos insumos'!$D$4,IF(C31="Dublagem Cretone HM50",'Custos insumos'!$D$26,IF(C31="Dublagem Cretone HM70",'Custos insumos'!$F$10,))))))))))))) -> 0 | N31: =IF(B31="Texion Textil",0,IF(B31="Três Elos",0,IF(C31="Malha",0,IF(C31="Dublagem Cretone",'Custos insumos'!$D$23,IF(C31="Dublagem Spun",'Custos insumos'!$D$19,IF(C31="Espelhamento",0,IF(C31="Espelhamento 2x",0,IF(C31="Esp. + Pel.",0,IF(C31="Pel. + Spun",'Custos insumos'!$D$19,IF(C31="Dublagem Cretone PES",'Custos insumos'!$F$25,IF(C31="Dublagem Barreira",'Custos insumos'!$D$22,))))))))))) -> 0
A32: ok | B32: Ecosimple Ind. | C32: Fel. + Cal. | D32: Diversos | E32: 4 | F32: 4.25 | G32: 4.2 | H32: metro linear | I32: =G32/E32 -> 1.05 | J32: 45260 | K32: Felpar e termofixar | L32: =G32-M32-N32 -> 4.2 | M32: =IF(B32="Texion Textil",0,IF(C32="Malha",'Custos insumos'!$B$24,IF(C32="Dublagem Cretone",'Custos insumos'!$D$7,IF(C32="Dublagem Spun",'Custos insumos'!$D$4,IF(C32="Espelhamento",'Custos insumos'!$B$11,IF(C32="Espelhamento 2x",2*'Custos insumos'!$B$11,IF(C32="Esp. + Pel.",'Custos insumos'!$B$11,IF(C32="Pel. + Spun",'Custos insumos'!$D$4,IF(C32="Dublagem Cretone PES",'Custos insumos'!$D$7,IF(C32="Dublagem Barreira",'Custos insumos'!$D$11,IF(C32="Dublagem - MO + Filme",'Custos insumos'!$D$4,IF(C32="Dublagem Cretone HM50",'Custos insumos'!$D$26,IF(C32="Dublagem Cretone HM70",'Custos insumos'!$F$10,))))))))))))) -> 0 | N32: =IF(B32="Texion Textil",0,IF(B32="Três Elos",0,IF(C32="Malha",0,IF(C32="Dublagem Cretone",'Custos insumos'!$D$23,IF(C32="Dublagem Spun",'Custos insumos'!$D$19,IF(C32="Espelhamento",0,IF(C32="Espelhamento 2x",0,IF(C32="Esp. + Pel.",0,IF(C32="Pel. + Spun",'Custos insumos'!$D$19,IF(C32="Dublagem Cretone PES",'Custos insumos'!$F$25,IF(C32="Dublagem Barreira",'Custos insumos'!$D$22,))))))))))) -> 0
A33: ok | B33: Ecosimple Ind. | C33: Dublagem Juta | D33: Juta | E33: 1 | G33: 4.55 | H33: metro linear | I33: =G33/E33 -> 4.55 | J33: 45260 | K33: Insumos fornecidos por Tapajos | L33: =G33-M33-N33 -> 4.05 | M33: =IF(B33="Texion Textil",0,IF(C33="Malha",'Custos insumos'!$B$24,IF(C33="Dublagem Cretone",'Custos insumos'!$D$7,IF(C33="Dublagem Spun",'Custos insumos'!$D$4,IF(C33="Espelhamento",'Custos insumos'!$B$11,IF(C33="Espelhamento 2x",2*'Custos insumos'!$B$11,IF(C33="Esp. + Pel.",'Custos insumos'!$B$11,IF(C33="Pel. + Spun",'Custos insumos'!$D$4,IF(C33="Dublagem Cretone PES",'Custos insumos'!$D$7,IF(C33="Dublagem Barreira",'Custos insumos'!$D$11,IF(C33="Dublagem - MO + Filme",'Custos insumos'!$D$4,IF(C33="Dublagem Cretone HM50",'Custos insumos'!$D$26,IF(C33="Dublagem Cretone HM70",'Custos insumos'!$F$10,))))))))))))) -> 0 | N33: 0.5
A34: ok | B34: Ecosimple Ind. | C34: Dublagem Cretone - MO (Juta) | D34: Apenas cola (HM35; L:1,55m) e MO | E34: 1 | F34: 6.19 | G34: 2.9 | H34: metro linear | I34: =G34/E34 -> 2.9 | J34: 45260 | K34: Insumos fornecidos por Tapajos | L34: =G34-M34-N34 -> 2.9 | M34: =IF(B34="Texion Textil",0,IF(C34="Malha",'Custos insumos'!$B$24,IF(C34="Dublagem Cretone",'Custos insumos'!$D$7,IF(C34="Dublagem Spun",'Custos insumos'!$D$4,IF(C34="Espelhamento",'Custos insumos'!$B$11,IF(C34="Espelhamento 2x",2*'Custos insumos'!$B$11,IF(C34="Esp. + Pel.",'Custos insumos'!$B$11,IF(C34="Pel. + Spun",'Custos insumos'!$D$4,IF(C34="Dublagem Cretone PES",'Custos insumos'!$D$7,IF(C34="Dublagem Barreira",'Custos insumos'!$D$11,IF(C34="Dublagem - MO + Filme",'Custos insumos'!$D$4,IF(C34="Dublagem Cretone HM50",'Custos insumos'!$D$26,IF(C34="Dublagem Cretone HM70",'Custos insumos'!$F$10,))))))))))))) -> 0 | N34: =IF(B34="Texion Textil",0,IF(B34="Três Elos",0,IF(C34="Malha",0,IF(C34="Dublagem Cretone",'Custos insumos'!$D$23,IF(C34="Dublagem Spun",'Custos insumos'!$D$19,IF(C34="Espelhamento",0,IF(C34="Espelhamento 2x",0,IF(C34="Esp. + Pel.",0,IF(C34="Pel. + Spun",'Custos insumos'!$D$19,IF(C34="Dublagem Cretone PES",'Custos insumos'!$F$25,IF(C34="Dublagem Barreira",'Custos insumos'!$D$22,))))))))))) -> 0
A35: ok | B35: Ecosimple Ind. | C35: Dublagem Cretone | D35: Dublagem Tupy/New Tweed | E35: 1 | F35: 6.19 | G35: 6.1 | H35: metro linear | I35: =G35/E35 -> 6.1 | J35: 45260 | K35: Insumos fornecidos por Tapajos | L35: =G35-M35-N35 -> 1.81 | M35: =IF(B35="Texion Textil",0,IF(C35="Malha",'Custos insumos'!$B$24,IF(C35="Dublagem Cretone",'Custos insumos'!$D$7,IF(C35="Dublagem Spun",'Custos insumos'!$D$4,IF(C35="Espelhamento",'Custos insumos'!$B$11,IF(C35="Espelhamento 2x",2*'Custos insumos'!$B$11,IF(C35="Esp. + Pel.",'Custos insumos'!$B$11,IF(C35="Pel. + Spun",'Custos insumos'!$D$4,IF(C35="Dublagem Cretone PES",'Custos insumos'!$D$7,IF(C35="Dublagem Barreira",'Custos insumos'!$D$11,IF(C35="Dublagem - MO + Filme",'Custos insumos'!$D$4,IF(C35="Dublagem Cretone HM50",'Custos insumos'!$D$26,IF(C35="Dublagem Cretone HM70",'Custos insumos'!$F$10,))))))))))))) -> 1.962 | N35: =IF(B35="Texion Textil",0,IF(B35="Três Elos",0,IF(C35="Malha",0,IF(C35="Dublagem Cretone",'Custos insumos'!$D$23,IF(C35="Dublagem Spun",'Custos insumos'!$D$19,IF(C35="Espelhamento",0,IF(C35="Espelhamento 2x",0,IF(C35="Esp. + Pel.",0,IF(C35="Pel. + Spun",'Custos insumos'!$D$19,IF(C35="Dublagem Cretone PES",'Custos insumos'!$F$25,IF(C35="Dublagem Barreira",'Custos insumos'!$D$22,))))))))))) -> 2.328
A36: ok | B36: Ecosimple Ind. | C36: Dublagem Cretone PES - 1,6 | D36: 1,60m | E36: 1 | G36: 4.6 | H36: metro linear | I36: =G36/E36 -> 4.6 | J36: 45260 | K36: Insumos fornecidos por Tapajos | L36: =G36-M36-N36 -> 1.3312 | M36: ='Custos insumos'!F5 -> 0.9408 | N36: ='Custos insumos'!F25 -> 2.328
A37: ok | B37: Ecosimple Ind. | C37: Dublagem Cretone PES | E37: 1 | G37: 4.9 | H37: metro linear | I37: =G37/E37 -> 4.9 | J37: 45260 | K37: Insumos fornecidos por Tapajos | L37: =G37-M37-N37 -> 0.61 | M37: =IF(B37="Texion Textil",0,IF(C37="Malha",'Custos insumos'!$B$24,IF(C37="Dublagem Cretone",'Custos insumos'!$D$7,IF(C37="Dublagem Spun",'Custos insumos'!$D$4,IF(C37="Espelhamento",'Custos insumos'!$B$11,IF(C37="Espelhamento 2x",2*'Custos insumos'!$B$11,IF(C37="Esp. + Pel.",'Custos insumos'!$B$11,IF(C37="Pel. + Spun",'Custos insumos'!$D$4,IF(C37="Dublagem Cretone PES",'Custos insumos'!$D$7,IF(C37="Dublagem Barreira",'Custos insumos'!$D$11,IF(C37="Dublagem - MO + Filme",'Custos insumos'!$D$4,IF(C37="Dublagem Cretone HM50",'Custos insumos'!$D$26,IF(C37="Dublagem Cretone HM70",'Custos insumos'!$F$10,))))))))))))) -> 1.962 | N37: =IF(B37="Texion Textil",0,IF(B37="Três Elos",0,IF(C37="Malha",0,IF(C37="Dublagem Cretone",'Custos insumos'!$D$23,IF(C37="Dublagem Spun",'Custos insumos'!$D$19,IF(C37="Espelhamento",0,IF(C37="Espelhamento 2x",0,IF(C37="Esp. + Pel.",0,IF(C37="Pel. + Spun",'Custos insumos'!$D$19,IF(C37="Dublagem Cretone PES",'Custos insumos'!$F$25,IF(C37="Dublagem Barreira",'Custos insumos'!$D$22,))))))))))) -> 2.328
A38: ok | B38: Ecosimple Ind. | C38: Dublagem Spun | D38: Diversos | E38: 1 | F38: 4.63 | G38: 4.6 | H38: metro linear | I38: =G38/E38 -> 4.6 | J38: 45260 | K38: Insumos fornecidos por Tapajos | L38: =G38-M38-N38 -> 2.5858 | M38: =IF(B38="Texion Textil",0,IF(C38="Malha",'Custos insumos'!$B$24,IF(C38="Dublagem Cretone",'Custos insumos'!$D$7,IF(C38="Dublagem Spun",'Custos insumos'!$D$4,IF(C38="Espelhamento",'Custos insumos'!$B$11,IF(C38="Espelhamento 2x",2*'Custos insumos'!$B$11,IF(C38="Esp. + Pel.",'Custos insumos'!$B$11,IF(C38="Pel. + Spun",'Custos insumos'!$D$4,IF(C38="Dublagem Cretone PES",'Custos insumos'!$D$7,IF(C38="Dublagem Barreira",'Custos insumos'!$D$11,IF(C38="Dublagem - MO + Filme",'Custos insumos'!$D$4,IF(C38="Dublagem Cretone HM50",'Custos insumos'!$D$26,IF(C38="Dublagem Cretone HM70",'Custos insumos'!$F$10,))))))))))))) -> 1.1232 | N38: =IF(B38="Texion Textil",0,IF(B38="Três Elos",0,IF(C38="Malha",0,IF(C38="Dublagem Cretone",'Custos insumos'!$D$23,IF(C38="Dublagem Spun",'Custos insumos'!$D$19,IF(C38="Espelhamento",0,IF(C38="Espelhamento 2x",0,IF(C38="Esp. + Pel.",0,IF(C38="Pel. + Spun",'Custos insumos'!$D$19,IF(C38="Dublagem Cretone PES",'Custos insumos'!$F$25,IF(C38="Dublagem Barreira",'Custos insumos'!$D$22,))))))))))) -> 0.891
A39: ok | B39: Ecosimple Ind. | C39: Espelhamento | D39: C/ Filme Single | E39: 1 | F39: 2.76 | G39: 2.75 | H39: metro linear | I39: =G39/E39 -> 2.75 | J39: 45260 | K39: Espelhamento - TBU BC - Insumos fornecidos por Tapajos | L39: =G39-M39-N39 -> 1.6914997 | M39: =IF(B39="Texion Textil",0,IF(C39="Malha",'Custos insumos'!$B$24,IF(C39="Dublagem Cretone",'Custos insumos'!$D$7,IF(C39="Dublagem Spun",'Custos insumos'!$D$4,IF(C39="Espelhamento",'Custos insumos'!$B$11,IF(C39="Espelhamento 2x",2*'Custos insumos'!$B$11,IF(C39="Esp. + Pel.",'Custos insumos'!$B$11,IF(C39="Pel. + Spun",'Custos insumos'!$D$4,IF(C39="Dublagem Cretone PES",'Custos insumos'!$D$7,IF(C39="Dublagem Barreira",'Custos insumos'!$D$11,IF(C39="Dublagem - MO + Filme",'Custos insumos'!$D$4,IF(C39="Dublagem Cretone HM50",'Custos insumos'!$D$26,IF(C39="Dublagem Cretone HM70",'Custos insumos'!$F$10,))))))))))))) -> 1.0585003 | N39: =IF(B39="Texion Textil",0,IF(B39="Três Elos",0,IF(C39="Malha",0,IF(C39="Dublagem Cretone",'Custos insumos'!$D$23,IF(C39="Dublagem Spun",'Custos insumos'!$D$19,IF(C39="Espelhamento",0,IF(C39="Espelhamento 2x",0,IF(C39="Esp. + Pel.",0,IF(C39="Pel. + Spun",'Custos insumos'!$D$19,IF(C39="Dublagem Cretone PES",'Custos insumos'!$F$25,IF(C39="Dublagem Barreira",'Custos insumos'!$D$22,))))))))))) -> 0
A40: ok | B40: Ecosimple Ind. | C40: Espelhamento anti-chama | D40: Filme + Mão de obra | E40: 1 | F40: 4.6 | G40: 4.6 | H40: metro linear | I40: =G40/E40 -> 4.6 | J40: 45260 | K40: Espelhamento - Anti chama 150 ou 100 - Insumos fornecidos por Tapajos | L40: =G40-M40-N40 -> 4.6 | M40: =IF(B40="Texion Textil",0,IF(C40="Malha",'Custos insumos'!$B$24,IF(C40="Dublagem Cretone",'Custos insumos'!$D$7,IF(C40="Dublagem Spun",'Custos insumos'!$D$4,IF(C40="Espelhamento",'Custos insumos'!$B$11,IF(C40="Espelhamento 2x",2*'Custos insumos'!$B$11,IF(C40="Esp. + Pel.",'Custos insumos'!$B$11,IF(C40="Pel. + Spun",'Custos insumos'!$D$4,IF(C40="Dublagem Cretone PES",'Custos insumos'!$D$7,IF(C40="Dublagem Barreira",'Custos insumos'!$D$11,IF(C40="Dublagem - MO + Filme",'Custos insumos'!$D$4,IF(C40="Dublagem Cretone HM50",'Custos insumos'!$D$26,IF(C40="Dublagem Cretone HM70",'Custos insumos'!$F$10,))))))))))))) -> 0 | N40: =IF(B40="Texion Textil",0,IF(B40="Três Elos",0,IF(C40="Malha",0,IF(C40="Dublagem Cretone",'Custos insumos'!$D$23,IF(C40="Dublagem Spun",'Custos insumos'!$D$19,IF(C40="Espelhamento",0,IF(C40="Espelhamento 2x",0,IF(C40="Esp. + Pel.",0,IF(C40="Pel. + Spun",'Custos insumos'!$D$19,IF(C40="Dublagem Cretone PES",'Custos insumos'!$F$25,IF(C40="Dublagem Barreira",'Custos insumos'!$D$22,))))))))))) -> 0
...

Sheet 2025
B1: Cliente | C1: Processo | D1: Artigo | E1: Passadas | F1: Valor anterior | G1: Valor atual | H1: Unid | I1: Preço/metro | J1: Data de atualização | K1: Obs | L1: MO | M1: Colas | N1: Forro | P1: Margem | Q1: Valor de venda por hora | R1: Produtividade m/por hora | S1: Custo de produção por hora | T1: CHH | U1: CMH | V1: CA | X1: CHH | Y1: CMH | Z1: CA
B2: Ademir Maceti | C2: Calandra | E2: 1 | F2: 0.65 | G2: =F2 -> 0.65 | H2: metro linear | J2: 45663 | L2: =G2-M2-N2 -> 0.65 | P2: =(Q2-S2)/Q2 -> 0.24765714 | Q2: =G2*R2 -> 227.5 | R2: {=_xlfn.IFS(C2="Calandra",(350),C2="Peletização",(421),C2="Dublagem Spun",(250),C2="Dublagem Cretone PES",(180),C2="Felpagem",(270/E2),C2="Emborrachamento",(200),C2="Espelhamento",(250),C2="Malha",(1),C2="Dublagem Cretone",(180),C2="Malha",(1),C2="Dublagem Spun - MO",250,C2="Dublagem Cretone - MO",180,C2="Dublagem Cretone PES - MO",180,C2="Espelhamento - MO",250,C2="Emborrachamento",100,C2="Malha",0,C2="Dublagem Barreira",100,C2="Pel. + Cal.",350,C2="Fel. + Pel. + Cal.",270,C2="Pel. + Spun",250,C2="Espelhamento - L: 1,45m",200,C2="Espelhamento - L: 1,65m",200,C2="Estampagem",100,C2="Fel. + Cal.",270,C2="Dublagem Juta",180,C2="Dublagem Cretone - MO (Juta)",180,C2="Dublagem Tapete",150,C2="Esp. + Pel.",200,C2="Espelhamento 2x",100)} -> 350 | S2: =(T2*X2)+(U2*Y2)+(V2*Z2)+((M2+N2)*(R2)) -> 171.158 | T2: {=_xlfn.IFS(C2="Calandra",0.4,C2="Felpagem",0.3,C2="Dublagem Spun",0.8,C2="Dublagem Cretone",0.8,C2="Dublagem Cretone PES",0.8,C2="Espelhamento",0.8,C2="Peletização",0.5,C2="Dublagem Spun - MO",0.8,C2="Dublagem Cretone - MO",0.8,C2="Dublagem Cretone PES - MO",0.8,C2="Espelhamento - MO",0.8,C2="Emborrachamento",1,C2="Malha",0,C2="Dublagem Barreira",1,C2="Pel. + Cal.",0.4,C2="Fel. + Pel. + Cal.",0.5,C2="Pel. + Spun",0.8,C2="Espelhamento - L: 1,45m",0.8,C2="Espelhamento - L: 1,65m",0.8,C2="Estampagem",1,C2="Fel. + Cal.",0.4,C2="Dublagem Juta",0.8,C2="Dublagem Cretone - MO (Juta)",0.8,C2="Dublagem Tapete",0.8,C2="Esp. + Pel.",0.8,C2="Espelhamento 2x",0.8)} -> 0.4 | U2: 1 | V2: 1 | X2: 39.67 | Y2: 38.51 | Z2: 116.78
B3: Ademir Maceti | C3: Emborrachamento | E3: 1 | F3: =4.1+1.5 -> 5.6 | G3: =F3 -> 5.6 | H3: metro linear | J3: 45663 | L3: =G3-M3-N3 -> 2.1 | M3: 3.5 | P3: =(Q3-S3)/Q3 -> 0.20092857 | Q3: =G3*R3 -> 1120 | R3: {=_xlfn.IFS(C3="Calandra",(350),C3="Peletização",(421),C3="Dublagem Spun",(250),C3="Dublagem Cretone PES",(180),C3="Felpagem",(270/E3),C3="Emborrachamento",(200),C3="Espelhamento",(250),C3="Malha",(1),C3="Dublagem Cretone",(180),C3="Malha",(1),C3="Dublagem Spun - MO",250,C3="Dublagem Cretone - MO",180,C3="Dublagem Cretone PES - MO",180,C3="Espelhamento - MO",250,C3="Emborrachamento",100,C3="Malha",0,C3="Dublagem Barreira",100,C3="Pel. + Cal.",350,C3="Fel. + Pel. + Cal.",270,C3="Pel. + Spun",250,C3="Espelhamento - L: 1,45m",200,C3="Espelhamento - L: 1,65m",200,C3="Estampagem",100,C3="Fel. + Cal.",270,C3="Dublagem Juta",180,C3="Dublagem Cretone - MO (Juta)",180,C3="Dublagem Tapete",150,C3="Esp. + Pel.",200,C3="Espelhamento 2x",100)} -> 200 | S3: =(T3*X3)+(U3*Y3)+(V3*Z3)+((M3+N3)*(R3)) -> 894.96 | T3: {=_xlfn.IFS(C3="Calandra",0.4,C3="Felpagem",0.3,C3="Dublagem Spun",0.8,C3="Dublagem Cretone",0.8,C3="Dublagem Cretone PES",0.8,C3="Espelhamento",0.8,C3="Peletização",0.5,C3="Dublagem Spun - MO",0.8,C3="Dublagem Cretone - MO",0.8,C3="Dublagem Cretone PES - MO",0.8,C3="Espelhamento - MO",0.8,C3="Emborrachamento",1,C3="Malha",0,C3="Dublagem Barreira",1,C3="Pel. + Cal.",0.4,C3="Fel. + Pel. + Cal.",0.5,C3="Pel. + Spun",0.8,C3="Espelhamento - L: 1,45m",0.8,C3="Espelhamento - L: 1,65m",0.8,C3="Estampagem",1,C3="Fel. + Cal.",0.4,C3="Dublagem Juta",0.8,C3="Dublagem Cretone - MO (Juta)",0.8,C3="Dublagem Tapete",0.8,C3="Esp. + Pel.",0.8,C3="Espelhamento 2x",0.8)} -> 1 | U3: 1 | V3: 1 | X3: 39.67 | Y3: 38.51 | Z3: 116.78
B4: AG Textil Eireli | C4: Peletização | E4: 1 | F4: 0.65 | G4: =F4 -> 0.65 | H4: metro linear | I4: =G4/E4 -> 0.65 | J4: 45663 | L4: =G4-M4-N4 -> 0.65 | M4: =IF(B4="Texion Textil",0,IF(C4="Malha",'Custos insumos'!$B$24,IF(C4="Dublagem Cretone",'Custos insumos'!$D$7,IF(C4="Dublagem Spun",'Custos insumos'!$D$4,IF(C4="Espelhamento",'Custos insumos'!$B$11,IF(C4="Espelhamento 2x",2*'Custos insumos'!$B$11,IF(C4="Esp. + Pel.",'Custos insumos'!$B$11,IF(C4="Pel. + Spun",'Custos insumos'!$D$4,IF(C4="Dublagem Cretone PES",'Custos insumos'!$D$7,IF(C4="Dublagem Barreira",'Custos insumos'!$D$11,IF(C4="Dublagem - MO + Filme",'Custos insumos'!$D$4,))))))))))) -> 0 | N4: =IF(B4="Texion Textil",0,IF(B4="Três Elos",0,IF(C4="Malha",0,IF(C4="Dublagem Cretone",'Custos insumos'!$D$23,IF(C4="Dublagem Spun",'Custos insumos'!$D$19,IF(C4="Espelhamento",0,IF(C4="Espelhamento 2x",0,IF(C4="Esp. + Pel.",0,IF(C4="Pel. + Spun",'Custos insumos'!$D$19,IF(C4="Dublagem Cretone PES",'Custos insumos'!$F$25,IF(C4="Dublagem Barreira",'Custos insumos'!$D$22,))))))))))) -> 0 | P4: =(Q4-S4)/Q4 -> 0.3600402 | Q4: =G4*R4 -> 273.65 | R4: {=_xlfn.IFS(C4="Calandra",(350),C4="Peletização",(421),C4="Dublagem Spun",(250),C4="Dublagem Cretone PES",(180),C4="Felpagem",(270/E4),C4="Emborrachamento",(200),C4="Espelhamento",(250),C4="Malha",(1),C4="Dublagem Cretone",(180),C4="Malha",(1),C4="Dublagem Spun - MO",250,C4="Dublagem Cretone - MO",180,C4="Dublagem Cretone PES - MO",180,C4="Espelhamento - MO",250,C4="Emborrachamento",100,C4="Malha",0,C4="Dublagem Barreira",100,C4="Pel. + Cal.",350,C4="Fel. + Pel. + Cal.",270,C4="Pel. + Spun",250,C4="Espelhamento - L: 1,45m",200,C4="Espelhamento - L: 1,65m",200,C4="Estampagem",100,C4="Fel. + Cal.",270,C4="Dublagem Juta",180,C4="Dublagem Cretone - MO (Juta)",180,C4="Dublagem Tapete",150,C4="Esp. + Pel.",200,C4="Espelhamento 2x",100)} -> 421 | S4: =(T4*X4)+(U4*Y4)+(V4*Z4)+((M4+N4)*(R4)) -> 175.125 | T4: {=_xlfn.IFS(C4="Calandra",0.4,C4="Felpagem",0.3,C4="Dublagem Spun",0.8,C4="Dublagem Cretone",0.8,C4="Dublagem Cretone PES",0.8,C4="Espelhamento",0.8,C4="Peletização",0.5,C4="Dublagem Spun - MO",0.8,C4="Dublagem Cretone - MO",0.8,C4="Dublagem Cretone PES - MO",0.8,C4="Espelhamento - MO",0.8,C4="Emborrachamento",1,C4="Malha",0,C4="Dublagem Barreira",1,C4="Pel. + Cal.",0.4,C4="Fel. + Pel. + Cal.",0.5,C4="Pel. + Spun",0.8,C4="Espelhamento - L: 1,45m",0.8,C4="Espelhamento - L: 1,65m",0.8,C4="Estampagem",1,C4="Fel. + Cal.",0.4,C4="Dublagem Juta",0.8,C4="Dublagem Cretone - MO (Juta)",0.8,C4="Dublagem Tapete",0.8,C4="Esp. + Pel.",0.8,C4="Espelhamento 2x",0.8)} -> 0.5 | U4: 1 | V4: 1 | X4: 39.67 | Y4: 38.51 | Z4: 116.78
B5: Air Slaid | C5: Malha | E5: 1 | F5: 20.9 | G5: 22.9 | H5: kg | I5: =G5/E5 -> 22.9 | J5: 45663 | L5: =G5-M5-N5 -> 10.4 | M5: =IF(B5="Texion Textil",0,IF(C5="Malha",'Custos insumos'!$B$24,IF(C5="Dublagem Cretone",'Custos insumos'!$D$7,IF(C5="Dublagem Spun",'Custos insumos'!$D$4,IF(C5="Espelhamento",'Custos insumos'!$B$11,IF(C5="Espelhamento 2x",2*'Custos insumos'!$B$11,IF(C5="Esp. + Pel.",'Custos insumos'!$B$11,IF(C5="Pel. + Spun",'Custos insumos'!$D$4,IF(C5="Dublagem Cretone PES",'Custos insumos'!$D$7,IF(C5="Dublagem Barreira",'Custos insumos'!$D$11,IF(C5="Dublagem - MO + Filme",'Custos insumos'!$D$4,))))))))))) -> 12.5 | N5: =IF(B5="Texion Textil",0,IF(B5="Três Elos",0,IF(C5="Malha",0,IF(C5="Dublagem Cretone",'Custos insumos'!$D$23,IF(C5="Dublagem Spun",'Custos insumos'!$D$19,IF(C5="Espelhamento",0,IF(C5="Espelhamento 2x",0,IF(C5="Esp. + Pel.",0,IF(C5="Pel. + Spun",'Custos insumos'!$D$19,IF(C5="Dublagem Cretone PES",'Custos insumos'!$F$25,IF(C5="Dublagem Barreira",'Custos insumos'!$D$22,))))))))))) -> 0 | P5: =(Q5-S5)/Q5 -> -6.3270742 | Q5: =G5*R5 -> 22.9 | R5: {=_xlfn.IFS(C5="Calandra",(350),C5="Peletização",(421),C5="Dublagem Spun",(250),C5="Dublagem Cretone PES",(180),C5="Felpagem",(270/E5),C5="Emborrachamento",(200),C5="Espelhamento",(250),C5="Malha",(1),C5="Dublagem Cretone",(180),C5="Malha",(1),C5="Dublagem Spun - MO",250,C5="Dublagem Cretone - MO",180,C5="Dublagem Cretone PES - MO",180,C5="Espelhamento - MO",250,C5="Emborrachamento",100,C5="Malha",0,C5="Dublagem Barreira",100,C5="Pel. + Cal.",350,C5="Fel. + Pel. + Cal.",270,C5="Pel. + Spun",250,C5="Espelhamento - L: 1,45m",200,C5="Espelhamento - L: 1,65m",200,C5="Estampagem",100,C5="Fel. + Cal.",270,C5="Dublagem Juta",180,C5="Dublagem Cretone - MO (Juta)",180,C5="Dublagem Tapete",150,C5="Esp. + Pel.",200,C5="Espelhamento 2x",100)} -> 1 | S5: =(T5*X5)+(U5*Y5)+(V5*Z5)+((M5+N5)*(R5)) -> 167.79 | T5: {=_xlfn.IFS(C5="Calandra",0.4,C5="Felpagem",0.3,C5="Dublagem Spun",0.8,C5="Dublagem Cretone",0.8,C5="Dublagem Cretone PES",0.8,C5="Espelhamento",0.8,C5="Peletização",0.5,C5="Dublagem Spun - MO",0.8,C5="Dublagem Cretone - MO",0.8,C5="Dublagem Cretone PES - MO",0.8,C5="Espelhamento - MO",0.8,C5="Emborrachamento",1,C5="Malha",0,C5="Dublagem Barreira",1,C5="Pel. + Cal.",0.4,C5="Fel. + Pel. + Cal.",0.5,C5="Pel. + Spun",0.8,C5="Espelhamento - L: 1,45m",0.8,C5="Espelhamento - L: 1,65m",0.8,C5="Estampagem",1,C5="Fel. + Cal.",0.4,C5="Dublagem Juta",0.8,C5="Dublagem Cretone - MO (Juta)",0.8,C5="Dublagem Tapete",0.8,C5="Esp. + Pel.",0.8,C5="Espelhamento 2x",0.8)} -> 0 | U5: 1 | V5: 1 | X5: 39.67 | Y5: 38.51 | Z5: 116.78
B6: Aparatos | C6: Dublagem Cretone PES | E6: 1 | F6: 6.5 | G6: =F6 -> 6.5 | H6: metro linear | I6: =G6/E6 -> 6.5 | J6: 45663 | K6: Insumos fornecidos por Tapajos | L6: =G6-M6-N6 -> 2.21 | M6: =IF(B6="Texion Textil",0,IF(C6="Malha",'Custos insumos'!$B$24,IF(C6="Dublagem Cretone",'Custos insumos'!$D$7,IF(C6="Dublagem Spun",'Custos insumos'!$D$4,IF(C6="Espelhamento",'Custos insumos'!$B$11,IF(C6="Espelhamento 2x",2*'Custos insumos'!$B$11,IF(C6="Esp. + Pel.",'Custos insumos'!$B$11,IF(C6="Pel. + Spun",'Custos insumos'!$D$4,IF(C6="Dublagem Cretone PES",'Custos insumos'!$D$7,IF(C6="Dublagem Barreira",'Custos insumos'!$D$11,IF(C6="Dublagem - MO + Filme",'Custos insumos'!$D$4,IF(C6="Dublagem Cretone HM50",'Custos insumos'!$D$26,IF(C6="Dublagem Cretone HM70",'Custos insumos'!$F$10,))))))))))))) -> 1.962 | N6: =IF(B6="Texion Textil",0,IF(B6="Três Elos",0,IF(C6="Malha",0,IF(C6="Dublagem Cretone",'Custos insumos'!$D$23,IF(C6="Dublagem Spun",'Custos insumos'!$D$19,IF(C6="Espelhamento",0,IF(C6="Espelhamento 2x",0,IF(C6="Esp. + Pel.",0,IF(C6="Pel. + Spun",'Custos insumos'!$D$19,IF(C6="Dublagem Cretone PES",'Custos insumos'!$F$25,IF(C6="Dublagem Barreira",'Custos insumos'!$D$22,))))))))))) -> 2.328 | P6: =(Q6-S6)/Q6 -> 0.18014872 | Q6: =G6*R6 -> 1170 | R6: {=_xlfn.IFS(C6="Calandra",(350),C6="Peletização",(421),C6="Dublagem Spun",(250),C6="Dublagem Cretone PES",(180),C6="Felpagem",(270/E6),C6="Emborrachamento",(200),C6="Espelhamento",(250),C6="Malha",(1),C6="Dublagem Cretone",(180),C6="Malha",(1),C6="Dublagem Spun - MO",250,C6="Dublagem Cretone - MO",180,C6="Dublagem Cretone PES - MO",180,C6="Espelhamento - MO",250,C6="Emborrachamento",100,C6="Malha",0,C6="Dublagem Barreira",100,C6="Pel. + Cal.",350,C6="Fel. + Pel. + Cal.",270,C6="Pel. + Spun",250,C6="Espelhamento - L: 1,45m",200,C6="Espelhamento - L: 1,65m",200,C6="Estampagem",100,C6="Fel. + Cal.",270,C6="Dublagem Juta",180,C6="Dublagem Cretone - MO (Juta)",180,C6="Dublagem Tapete",150,C6="Esp. + Pel.",200,C6="Espelhamento 2x",100)} -> 180 | S6: =(T6*X6)+(U6*Y6)+(V6*Z6)+((M6+N6)*(R6)) -> 959.226 | T6: {=_xlfn.IFS(C6="Calandra",0.4,C6="Felpagem",0.3,C6="Dublagem Spun",0.8,C6="Dublagem Cretone",0.8,C6="Dublagem Cretone PES",0.8,C6="Espelhamento",0.8,C6="Peletização",0.5,C6="Dublagem Spun - MO",0.8,C6="Dublagem Cretone - MO",0.8,C6="Dublagem Cretone PES - MO",0.8,C6="Espelhamento - MO",0.8,C6="Emborrachamento",1,C6="Malha",0,C6="Dublagem Barreira",1,C6="Pel. + Cal.",0.4,C6="Fel. + Pel. + Cal.",0.5,C6="Pel. + Spun",0.8,C6="Espelhamento - L: 1,45m",0.8,C6="Espelhamento - L: 1,65m",0.8,C6="Estampagem",1,C6="Fel. + Cal.",0.4,C6="Dublagem Juta",0.8,C6="Dublagem Cretone - MO (Juta)",0.8,C6="Dublagem Tapete",0.8,C6="Esp. + Pel.",0.8,C6="Espelhamento 2x",0.8)} -> 0.8 | U6: 1 | V6: 1 | X6: 39.67 | Y6: 38.51 | Z6: 116.78
